Workbook

Sheet Dados
A1: Dataset: Funcionarios (employees.csv)
A2: ID | B2: Nome | C2: Departamento | D2: Cargo | E2: Cidade | F2: Salario | G2: Data Admissao | H2: Ativo | J2: Resumo Rapido
A3: 1 | B3: Ana | C3: Operações | D3: Analista Operações | E3: Porto Alegre | F3: 2955.07 | G3: 2021-01-31 | H3: Sim | J3: Total de funcionarios | K3: =COUNTA(A3:A54)
A4: 2 | B4: Carlos | D4: Analista Financeiro | E4: Brasília | F4: 4842.67 | G4: 2020-06-14 | H4: Sim | J4: Total de funcionarios ativos | K4: =COUNTIF(H3:H54,"Sim")
A5: 3 | B5: João | C5: Vendas | D5: Key Account | E5: Porto Alegre | F5: 8303.39 | G5: 2018-01-27 | H5: Sim | J5: Salario medio | K5: =AVERAGE(F3:F54)
A6: 4 | B6: Maria | C6: RH | D6: Analista RH | E6: Salvador | F6: 4102.85 | G6: 2019-02-01 | H6: Sim | J6: Maior salario | K6: =MAX(F3:F54)
A7: 5 | B7: Pedro | C7: Financeiro | D7: Analista Financeiro | E7: Salvador | G7: 2025-01-18 | H7: Sim | J7: Menor salario | K7: =MIN(F3:F54)
A8: 6 | B8: Fernanda | C8: RH | D8: Analista RH | E8: Manaus | F8: 9059.57 | G8: 2019-02-18 | H8: Sim | J8: Folha total | K8: =SUM(F3:F54)
A9: 7 | B9: Lucas | C9: RH | D9: Analista RH | E9: Curitiba | F9: 7459.35 | G9: 2019-12-02 | H9: Sim | J9: Nulos em salario | K9: =COUNTA(F3:F54)-COUNT(F3:F54)
A10: 8 | B10: Juliana | C10: Marketing | D10: Designer | E10: São Paulo | G10: 2018-08-18 | H10: Sim
A11: 9 | B11: Rafael | C11: Marketing | D11: Copywriter | E11: Manaus | F11: 4701.01 | G11: 2023-08-07 | H11: Sim
A12: 10 | B12: Camila | C12: Operações | D12: Gerente Ops | E12: Porto Alegre | G12: 2022-06-24 | H12: Sim
A13: 11 | B13: Bruno | C13: Operações | D13: Supervisor | E13: Fortaleza | F13: 7710.89 | G13: 2022-09-26 | H13: Sim
A14: 12 | B14: Larissa | C14: TI | D14: Analista | E14: Salvador | F14: 13862.23 | G14: 2024-01-09 | H14: Sim
A15: 13 | B15: Diego | C15: Operações | D15: Coordenador | E15: Rio de Janeiro | F15: 8825.71 | G15: 2020-01-02 | H15: Sim
A16: 14 | B16: Patrícia | C16: Vendas | D16: SDR | E16: Recife | F16: 9862.6 | G16: 2024-01-19 | H16: Não
A17: 15 | B17: Thiago | C17: RH | D17: Recruiter | E17: Rio de Janeiro | G17: 2020-09-13 | H17: Não
A18: 16 | B18: Renata | C18: Vendas | D18: Gerente de Contas | E18: Recife | F18: 8937.76 | G18: 2024-03-01 | H18: Sim
A19: 17 | B19: Felipe | C19: Operações | D19: Supervisor | E19: Salvador | F19: 7220.28 | G19: 2022-06-23 | H19: Não
A20: 18 | B20: Daniela | D20: Analista RH | E20: São Paulo | F20: 7324.01 | G20: 2020-07-31 | H20: Sim
A21: 19 | B21: Rodrigo | C21: RH | D21: Analista RH | E21: Curitiba | F21: 6842.01 | G21: 2021-02-14 | H21: Sim
A22: 20 | B22: Amanda | C22: Vendas | D22: Key Account | E22: Fortaleza | F22: 10267.47 | H22: Sim
A23: 21 | B23: Gustavo | C23: Operações | D23: Analista Operações | E23: Rio de Janeiro | F23: 3175.8 | G23: 2021-10-21 | H23: Sim
A24: 22 | B24: Vanessa | C24: RH | D24: Gerente RH | E24: Recife | F24: 5123.74 | H24: Sim
A25: 23 | B25: Eduardo | C25: TI | D25: Desenvolvedor | E25: Fortaleza | G25: 2023-06-13 | H25: Sim
A26: 24 | B26: Aline | C26: Financeiro | D26: Tesoureiro | E26: Manaus | F26: 9364.59 | G26: 2024-03-26 | H26: Sim
A27: 25 | B27: Marcos | C27: Marketing | D27: Analista Marketing | E27: Manaus | F27: 8983.8 | G27: 2018-08-23 | H27: Sim
A28: 26 | B28: Cristina | C28: TI | D28: Desenvolvedor | E28: Curitiba | F28: 5890.78 | G28: 2018-10-06 | H28: Sim
A29: 27 | B29: Leonardo | C29: TI | D29: Analista | E29: Salvador | F29: 10449.92 | G29: 2024-07-18 | H29: Sim
A30: 28 | B30: Priscila | D30: Controller | E30: Rio de Janeiro | F30: 12224.44 | G30: 2021-05-13 | H30: Sim
A31: 29 | B31: André | C31: Marketing | D31: Designer | E31: Rio de Janeiro | F31: 7047.08 | G31: 2019-06-27 | H31: Não
A32: 30 | B32: Tatiana | C32: Operações | D32: Coordenador | E32: Recife | F32: 6592.4 | G32: 2025-05-02 | H32: Sim
A33: 31 | B33: Vinícius | C33: TI | D33: Analista | E33: Brasília | F33: 14651.42 | G33: 2019-09-29 | H33: Sim
A34: 32 | B34: Mariana | C34: Marketing | E34: Fortaleza | F34: 5008.97 | G34: 2018-07-28 | H34: Sim
A35: 33 | B35: Leandro | E35: Recife | F35: 8318 | G35: 2024-03-09 | H35: Sim
A36: 34 | B36: Beatriz | C36: Marketing | D36: Analista Marketing | E36: Fortaleza | F36: 9676.76 | G36: 2024-07-13 | H36: Sim
A37: 35 | B37: Ricardo | C37: TI | D37: Arquiteto | E37: Salvador | F37: 7730.99 | G37: 2020-10-19 | H37: Sim
A38: 36 | B38: Érica | C38: Vendas | D38: Gerente de Contas | E38: São Paulo | F38: 10781.45 | G38: 2019-12-27 | H38: Não
A39: 37 | B39: Matheus | C39: Operações | D39: Supervisor | E39: São Paulo | F39: 4454.2 | G39: 2019-03-19 | H39: Sim
A40: 38 | B40: Letícia | C40: RH | E40: Salvador | F40: 4949 | G40: 2025-05-27 | H40: Sim
...

Sheet Filtros
A1: Exemplos de Filtros com Formulas Excel
A2: Descricao | B2: Formula Excel | E2: Descricao | F2: Formula Excel
A3: Contar TI | B3: =COUNTIF(Dados!C3:C54,"TI") | E3: COUNTIFS - TI E Ativo | F3: =COUNTIFS(Dados!C3:C54,"TI",Dados!H3:H54,"Sim")
A4: Contar ativos | B4: =COUNTIF(Dados!H3:H54,"Sim") | E4: SUMIFS - Vendas E Ativo | F4: =SUMIFS(Dados!F3:F54,Dados!C3:C54,"Vendas",Dados!H3:H54,"Sim")
A5: Contar salario > 8000 | B5: =COUNTIF(Dados!F3:F54,">8000") | E5: AVERAGEIFS - TI E > 5000 | F5: =AVERAGEIFS(Dados!F3:F54,Dados!C3:C54,"TI",Dados!F3:F54,">5000")
A6: Contar nulos salario | B6: =COUNTA(Dados!F3:F54)-COUNT(Dados!F3:F54) | E6: Nome maior salario | F6: =INDEX(Dados!B3:B54,MATCH(MAX(Dados!F3:F54),Dados!F3:F54,0))
A7: Soma salario TI | B7: =SUMIF(Dados!C3:C54,"TI",Dados!F3:F54) | E7: Nome menor salario | F7: =INDEX(Dados!B3:B54,MATCH(MIN(Dados!F3:F54),Dados!F3:F54,0))
A8: Soma salario > 5000 | B8: =SUMIF(Dados!F3:F54,">5000",Dados!F3:F54) | E8: 3o maior salario | F8: =LARGE(Dados!F3:F54,3)
A9: Media TI | B9: =AVERAGEIF(Dados!C3:C54,"TI",Dados!F3:F54) | E9: 3o menor salario | F9: =SMALL(Dados!F3:F54,3)
A10: Valor min salario | B10: =MIN(Dados!F3:F54) | E10: Unicos departamentos | F10: =SUMPRODUCT(1/COUNTIF(Dados!C3:C53,Dados!C3:C53))
A11: Valor max salario | B11: =MAX(Dados!F3:F54) | E11: % salario > 8000 | F11: =COUNTIF(Dados!F3:F54,">8000")/COUNTA(Dados!F3:F54)
A12: Total geral folha | B12: =SUM(Dados!F3:F54) | E12: Folha ativos | F12: =SUMIF(Dados!H3:H54,"Sim",Dados!F3:F54)
A14: Nota: As formulas acima referenciam a aba 'Dados'. Certifique-se de que ela existe.

Sheet Agrupamento
A1: Agrupamento por Departamento (equivalente ao GROUP BY)
A2: Departamento | B2: Qtd Funcionarios | C2: Salario Total | D2: Salario Medio | E2: Maior Salario | F2: Menor Salario | G2: % da Folha
A3: Financeiro | B3: =COUNTIF(Dados!C$3:C$54,A3) | C3: =SUMIF(Dados!C$3:C$54,A3,Dados!F$3:F$54) | D3: =IFERROR(AVERAGEIF(Dados!C$3:C$54,A3,Dados!F$3:F$54),0) | E3: =_xlfn.MAXIFS(Dados!F$3:F$54,Dados!C$3:C$54,A3) | F3: =_xlfn.MINIFS(Dados!F$3:F$54,Dados!C$3:C$54,A3) | G3: =C3/C$9
A4: Marketing | B4: =COUNTIF(Dados!C$3:C$54,A4) | C4: =SUMIF(Dados!C$3:C$54,A4,Dados!F$3:F$54) | D4: =IFERROR(AVERAGEIF(Dados!C$3:C$54,A4,Dados!F$3:F$54),0) | E4: =_xlfn.MAXIFS(Dados!F$3:F$54,Dados!C$3:C$54,A4) | F4: =_xlfn.MINIFS(Dados!F$3:F$54,Dados!C$3:C$54,A4) | G4: =C4/C$9
A5: Operacoes | B5: =COUNTIF(Dados!C$3:C$54,A5) | C5: =SUMIF(Dados!C$3:C$54,A5,Dados!F$3:F$54) | D5: =IFERROR(AVERAGEIF(Dados!C$3:C$54,A5,Dados!F$3:F$54),0) | E5: =_xlfn.MAXIFS(Dados!F$3:F$54,Dados!C$3:C$54,A5) | F5: =_xlfn.MINIFS(Dados!F$3:F$54,Dados!C$3:C$54,A5) | G5: =C5/C$9
A6: RH | B6: =COUNTIF(Dados!C$3:C$54,A6) | C6: =SUMIF(Dados!C$3:C$54,A6,Dados!F$3:F$54) | D6: =IFERROR(AVERAGEIF(Dados!C$3:C$54,A6,Dados!F$3:F$54),0) | E6: =_xlfn.MAXIFS(Dados!F$3:F$54,Dados!C$3:C$54,A6) | F6: =_xlfn.MINIFS(Dados!F$3:F$54,Dados!C$3:C$54,A6) | G6: =C6/C$9
A7: TI | B7: =COUNTIF(Dados!C$3:C$54,A7) | C7: =SUMIF(Dados!C$3:C$54,A7,Dados!F$3:F$54) | D7: =IFERROR(AVERAGEIF(Dados!C$3:C$54,A7,Dados!F$3:F$54),0) | E7: =_xlfn.MAXIFS(Dados!F$3:F$54,Dados!C$3:C$54,A7) | F7: =_xlfn.MINIFS(Dados!F$3:F$54,Dados!C$3:C$54,A7) | G7: =C7/C$9
A8: Vendas | B8: =COUNTIF(Dados!C$3:C$54,A8) | C8: =SUMIF(Dados!C$3:C$54,A8,Dados!F$3:F$54) | D8: =IFERROR(AVERAGEIF(Dados!C$3:C$54,A8,Dados!F$3:F$54),0) | E8: =_xlfn.MAXIFS(Dados!F$3:F$54,Dados!C$3:C$54,A8) | F8: =_xlfn.MINIFS(Dados!F$3:F$54,Dados!C$3:C$54,A8) | G8: =C8/C$9
A9: TOTAL | B9: =SUM(B3:B8) | C9: =SUM(C3:C8) | D9: =AVERAGE(Dados!F3:F54) | E9: =MAX(Dados!F3:F54) | F9: =MIN(Dados!F3:F54) | G9: =SUM(G3:G8)
A11: Nota: _xlfn.MAXIFS e _xlfn.MINIFS requerem Excel 2019 ou 365. Em versoes mais antigas, use MAX com IFERROR(INDEX...)

Sheet Datas
A1: Trabalhar com Datas no Excel
A2: Funcao / Descricao | B2: Formula (referencia: Dados!G3 = data_admissao) | E2: Calculo Avancado | F2: Formula
A3: Extrair Ano | B3: =YEAR(Dados!G3) | E3: Tempo de casa (dias) | F3: =TODAY()-Dados!G3
A4: Extrair Mes | B4: =MONTH(Dados!G3) | E4: Tempo de casa (anos) | F4: =YEARFRAC(Dados!G3,TODAY())
A5: Extrair Dia | B5: =DAY(Dados!G3) | E5: Tempo de casa (meses) | F5: =DATEDIF(Dados!G3,TODAY(),"M")
A6: Nome do Mes | B6: =TEXT(Dados!G3,"MMMM") | E6: Data + 30 dias | F6: =Dados!G3+30
A7: Dia da Semana (nome) | B7: =TEXT(Dados!G3,"DDDD") | E7: Primeiro dia do mes | F7: =DATE(YEAR(Dados!G3),MONTH(Dados!G3),1)
A8: Numero dia semana | B8: =WEEKDAY(Dados!G3,2) | E8: Ultimo dia do mes | F8: =EOMONTH(Dados!G3,0)
A9: Trimestre | B9: =INT((MONTH(Dados!G3)-1)/3)+1 | E9: Dias entre duas datas | F9: =_xlfn.DAYS(TODAY(),Dados!G3)
A10: Semana do ano | B10: =WEEKNUM(Dados!G3,2) | E10: Dias uteis entre datas | F10: =WORKDAY(Dados!G3,30)
A11: Hoje | B11: =TODAY() | E11: Filtrar ano 2023 | F11: =COUNTIF(Dados!G3:G54,">=01/01/2023")-COUNTIF(Dados!G3:G54,">=01/01/2024")
A12: Agora | B12: =NOW() | E12: Mais recente admissao | F12: =MAX(Dados!G3:G54)

Sheet Condicional
A1: Coluna Condicional — SE, IFS, IFERROR, SWITCH
A2: Nome | B2: Departamento | C2: Salario | D2: Nivel (SE aninhado) | E2: Nivel (IFS) | F2: Faixa Salarial | G2: Ativo Label
A3: Ana | B3: Operações | C3: 2955.07 | D3: =IF(C3>12000,"Especialista",IF(C3>8000,"Senior",IF(C3>5000,"Pleno","Junior"))) | E3: =_xlfn.IFS(C3>12000,"Especialista",C3>8000,"Senior",C3>5000,"Pleno",TRUE,"Junior") | F3: =IF(C3>10000,"Alto",IF(C3>6000,"Medio","Baixo")) | G3: =IF(Dados!H3="Sim","Ativo","Inativo")
A4: Carlos | C4: 4842.67 | D4: =IF(C4>12000,"Especialista",IF(C4>8000,"Senior",IF(C4>5000,"Pleno","Junior"))) | E4: =_xlfn.IFS(C4>12000,"Especialista",C4>8000,"Senior",C4>5000,"Pleno",TRUE,"Junior") | F4: =IF(C4>10000,"Alto",IF(C4>6000,"Medio","Baixo")) | G4: =IF(Dados!H4="Sim","Ativo","Inativo")
A5: João | B5: Vendas | C5: 8303.39 | D5: =IF(C5>12000,"Especialista",IF(C5>8000,"Senior",IF(C5>5000,"Pleno","Junior"))) | E5: =_xlfn.IFS(C5>12000,"Especialista",C5>8000,"Senior",C5>5000,"Pleno",TRUE,"Junior") | F5: =IF(C5>10000,"Alto",IF(C5>6000,"Medio","Baixo")) | G5: =IF(Dados!H5="Sim","Ativo","Inativo")
A6: Maria | B6: RH | C6: 4102.85 | D6: =IF(C6>12000,"Especialista",IF(C6>8000,"Senior",IF(C6>5000,"Pleno","Junior"))) | E6: =_xlfn.IFS(C6>12000,"Especialista",C6>8000,"Senior",C6>5000,"Pleno",TRUE,"Junior") | F6: =IF(C6>10000,"Alto",IF(C6>6000,"Medio","Baixo")) | G6: =IF(Dados!H6="Sim","Ativo","Inativo")
A7: Pedro | B7: Financeiro | D7: =IF(C7>12000,"Especialista",IF(C7>8000,"Senior",IF(C7>5000,"Pleno","Junior"))) | E7: =_xlfn.IFS(C7>12000,"Especialista",C7>8000,"Senior",C7>5000,"Pleno",TRUE,"Junior") | F7: =IF(C7>10000,"Alto",IF(C7>6000,"Medio","Baixo")) | G7: =IF(Dados!H7="Sim","Ativo","Inativo")
A8: Fernanda | B8: RH | C8: 9059.57 | D8: =IF(C8>12000,"Especialista",IF(C8>8000,"Senior",IF(C8>5000,"Pleno","Junior"))) | E8: =_xlfn.IFS(C8>12000,"Especialista",C8>8000,"Senior",C8>5000,"Pleno",TRUE,"Junior") | F8: =IF(C8>10000,"Alto",IF(C8>6000,"Medio","Baixo")) | G8: =IF(Dados!H8="Sim","Ativo","Inativo")
A9: Lucas | B9: RH | C9: 7459.35 | D9: =IF(C9>12000,"Especialista",IF(C9>8000,"Senior",IF(C9>5000,"Pleno","Junior"))) | E9: =_xlfn.IFS(C9>12000,"Especialista",C9>8000,"Senior",C9>5000,"Pleno",TRUE,"Junior") | F9: =IF(C9>10000,"Alto",IF(C9>6000,"Medio","Baixo")) | G9: =IF(Dados!H9="Sim","Ativo","Inativo")
A10: Juliana | B10: Marketing | D10: =IF(C10>12000,"Especialista",IF(C10>8000,"Senior",IF(C10>5000,"Pleno","Junior"))) | E10: =_xlfn.IFS(C10>12000,"Especialista",C10>8000,"Senior",C10>5000,"Pleno",TRUE,"Junior") | F10: =IF(C10>10000,"Alto",IF(C10>6000,"Medio","Baixo")) | G10: =IF(Dados!H10="Sim","Ativo","Inativo")
A11: Rafael | B11: Marketing | C11: 4701.01 | D11: =IF(C11>12000,"Especialista",IF(C11>8000,"Senior",IF(C11>5000,"Pleno","Junior"))) | E11: =_xlfn.IFS(C11>12000,"Especialista",C11>8000,"Senior",C11>5000,"Pleno",TRUE,"Junior") | F11: =IF(C11>10000,"Alto",IF(C11>6000,"Medio","Baixo")) | G11: =IF(Dados!H11="Sim","Ativo","Inativo")
A12: Camila | B12: Operações | D12: =IF(C12>12000,"Especialista",IF(C12>8000,"Senior",IF(C12>5000,"Pleno","Junior"))) | E12: =_xlfn.IFS(C12>12000,"Especialista",C12>8000,"Senior",C12>5000,"Pleno",TRUE,"Junior") | F12: =IF(C12>10000,"Alto",IF(C12>6000,"Medio","Baixo")) | G12: =IF(Dados!H12="Sim","Ativo","Inativo")
A13: Bruno | B13: Operações | C13: 7710.89 | D13: =IF(C13>12000,"Especialista",IF(C13>8000,"Senior",IF(C13>5000,"Pleno","Junior"))) | E13: =_xlfn.IFS(C13>12000,"Especialista",C13>8000,"Senior",C13>5000,"Pleno",TRUE,"Junior") | F13: =IF(C13>10000,"Alto",IF(C13>6000,"Medio","Baixo")) | G13: =IF(Dados!H13="Sim","Ativo","Inativo")
A14: Larissa | B14: TI | C14: 13862.23 | D14: =IF(C14>12000,"Especialista",IF(C14>8000,"Senior",IF(C14>5000,"Pleno","Junior"))) | E14: =_xlfn.IFS(C14>12000,"Especialista",C14>8000,"Senior",C14>5000,"Pleno",TRUE,"Junior") | F14: =IF(C14>10000,"Alto",IF(C14>6000,"Medio","Baixo")) | G14: =IF(Dados!H14="Sim","Ativo","Inativo")
A15: Diego | B15: Operações | C15: 8825.71 | D15: =IF(C15>12000,"Especialista",IF(C15>8000,"Senior",IF(C15>5000,"Pleno","Junior"))) | E15: =_xlfn.IFS(C15>12000,"Especialista",C15>8000,"Senior",C15>5000,"Pleno",TRUE,"Junior") | F15: =IF(C15>10000,"Alto",IF(C15>6000,"Medio","Baixo")) | G15: =IF(Dados!H15="Sim","Ativo","Inativo")
A16: Patrícia | B16: Vendas | C16: 9862.6 | D16: =IF(C16>12000,"Especialista",IF(C16>8000,"Senior",IF(C16>5000,"Pleno","Junior"))) | E16: =_xlfn.IFS(C16>12000,"Especialista",C16>8000,"Senior",C16>5000,"Pleno",TRUE,"Junior") | F16: =IF(C16>10000,"Alto",IF(C16>6000,"Medio","Baixo")) | G16: =IF(Dados!H16="Sim","Ativo","Inativo")
A17: Thiago | B17: RH | D17: =IF(C17>12000,"Especialista",IF(C17>8000,"Senior",IF(C17>5000,"Pleno","Junior"))) | E17: =_xlfn.IFS(C17>12000,"Especialista",C17>8000,"Senior",C17>5000,"Pleno",TRUE,"Junior") | F17: =IF(C17>10000,"Alto",IF(C17>6000,"Medio","Baixo")) | G17: =IF(Dados!H17="Sim","Ativo","Inativo")
A18: Renata | B18: Vendas | C18: 8937.76 | D18: =IF(C18>12000,"Especialista",IF(C18>8000,"Senior",IF(C18>5000,"Pleno","Junior"))) | E18: =_xlfn.IFS(C18>12000,"Especialista",C18>8000,"Senior",C18>5000,"Pleno",TRUE,"Junior") | F18: =IF(C18>10000,"Alto",IF(C18>6000,"Medio","Baixo")) | G18: =IF(Dados!H18="Sim","Ativo","Inativo")
A19: Felipe | B19: Operações | C19: 7220.28 | D19: =IF(C19>12000,"Especialista",IF(C19>8000,"Senior",IF(C19>5000,"Pleno","Junior"))) | E19: =_xlfn.IFS(C19>12000,"Especialista",C19>8000,"Senior",C19>5000,"Pleno",TRUE,"Junior") | F19: =IF(C19>10000,"Alto",IF(C19>6000,"Medio","Baixo")) | G19: =IF(Dados!H19="Sim","Ativo","Inativo")
A20: Daniela | C20: 7324.01 | D20: =IF(C20>12000,"Especialista",IF(C20>8000,"Senior",IF(C20>5000,"Pleno","Junior"))) | E20: =_xlfn.IFS(C20>12000,"Especialista",C20>8000,"Senior",C20>5000,"Pleno",TRUE,"Junior") | F20: =IF(C20>10000,"Alto",IF(C20>6000,"Medio","Baixo")) | G20: =IF(Dados!H20="Sim","Ativo","Inativo")
A21: Rodrigo | B21: RH | C21: 6842.01 | D21: =IF(C21>12000,"Especialista",IF(C21>8000,"Senior",IF(C21>5000,"Pleno","Junior"))) | E21: =_xlfn.IFS(C21>12000,"Especialista",C21>8000,"Senior",C21>5000,"Pleno",TRUE,"Junior") | F21: =IF(C21>10000,"Alto",IF(C21>6000,"Medio","Baixo")) | G21: =IF(Dados!H21="Sim","Ativo","Inativo")
A22: Amanda | B22: Vendas | C22: 10267.47 | D22: =IF(C22>12000,"Especialista",IF(C22>8000,"Senior",IF(C22>5000,"Pleno","Junior"))) | E22: =_xlfn.IFS(C22>12000,"Especialista",C22>8000,"Senior",C22>5000,"Pleno",TRUE,"Junior") | F22: =IF(C22>10000,"Alto",IF(C22>6000,"Medio","Baixo")) | G22: =IF(Dados!H22="Sim","Ativo","Inativo")
A23: Gustavo | B23: Operações | C23: 3175.8 | D23: =IF(C23>12000,"Especialista",IF(C23>8000,"Senior",IF(C23>5000,"Pleno","Junior"))) | E23: =_xlfn.IFS(C23>12000,"Especialista",C23>8000,"Senior",C23>5000,"Pleno",TRUE,"Junior") | F23: =IF(C23>10000,"Alto",IF(C23>6000,"Medio","Baixo")) | G23: =IF(Dados!H23="Sim","Ativo","Inativo")
A24: Vanessa | B24: RH | C24: 5123.74 | D24: =IF(C24>12000,"Especialista",IF(C24>8000,"Senior",IF(C24>5000,"Pleno","Junior"))) | E24: =_xlfn.IFS(C24>12000,"Especialista",C24>8000,"Senior",C24>5000,"Pleno",TRUE,"Junior") | F24: =IF(C24>10000,"Alto",IF(C24>6000,"Medio","Baixo")) | G24: =IF(Dados!H24="Sim","Ativo","Inativo")
A25: Eduardo | B25: TI | D25: =IF(C25>12000,"Especialista",IF(C25>8000,"Senior",IF(C25>5000,"Pleno","Junior"))) | E25: =_xlfn.IFS(C25>12000,"Especialista",C25>8000,"Senior",C25>5000,"Pleno",TRUE,"Junior") | F25: =IF(C25>10000,"Alto",IF(C25>6000,"Medio","Baixo")) | G25: =IF(Dados!H25="Sim","Ativo","Inativo")
A26: Aline | B26: Financeiro | C26: 9364.59 | D26: =IF(C26>12000,"Especialista",IF(C26>8000,"Senior",IF(C26>5000,"Pleno","Junior"))) | E26: =_xlfn.IFS(C26>12000,"Especialista",C26>8000,"Senior",C26>5000,"Pleno",TRUE,"Junior") | F26: =IF(C26>10000,"Alto",IF(C26>6000,"Medio","Baixo")) | G26: =IF(Dados!H26="Sim","Ativo","Inativo")
A27: Marcos | B27: Marketing | C27: 8983.8 | D27: =IF(C27>12000,"Especialista",IF(C27>8000,"Senior",IF(C27>5000,"Pleno","Junior"))) | E27: =_xlfn.IFS(C27>12000,"Especialista",C27>8000,"Senior",C27>5000,"Pleno",TRUE,"Junior") | F27: =IF(C27>10000,"Alto",IF(C27>6000,"Medio","Baixo")) | G27: =IF(Dados!H27="Sim","Ativo","Inativo")
A28: Cristina | B28: TI | C28: 5890.78 | D28: =IF(C28>12000,"Especialista",IF(C28>8000,"Senior",IF(C28>5000,"Pleno","Junior"))) | E28: =_xlfn.IFS(C28>12000,"Especialista",C28>8000,"Senior",C28>5000,"Pleno",TRUE,"Junior") | F28: =IF(C28>10000,"Alto",IF(C28>6000,"Medio","Baixo")) | G28: =IF(Dados!H28="Sim","Ativo","Inativo")
A29: Leonardo | B29: TI | C29: 10449.92 | D29: =IF(C29>12000,"Especialista",IF(C29>8000,"Senior",IF(C29>5000,"Pleno","Junior"))) | E29: =_xlfn.IFS(C29>12000,"Especialista",C29>8000,"Senior",C29>5000,"Pleno",TRUE,"Junior") | F29: =IF(C29>10000,"Alto",IF(C29>6000,"Medio","Baixo")) | G29: =IF(Dados!H29="Sim","Ativo","Inativo")
A30: Priscila | C30: 12224.44 | D30: =IF(C30>12000,"Especialista",IF(C30>8000,"Senior",IF(C30>5000,"Pleno","Junior"))) | E30: =_xlfn.IFS(C30>12000,"Especialista",C30>8000,"Senior",C30>5000,"Pleno",TRUE,"Junior") | F30: =IF(C30>10000,"Alto",IF(C30>6000,"Medio","Baixo")) | G30: =IF(Dados!H30="Sim","Ativo","Inativo")
A31: André | B31: Marketing | C31: 7047.08 | D31: =IF(C31>12000,"Especialista",IF(C31>8000,"Senior",IF(C31>5000,"Pleno","Junior"))) | E31: =_xlfn.IFS(C31>12000,"Especialista",C31>8000,"Senior",C31>5000,"Pleno",TRUE,"Junior") | F31: =IF(C31>10000,"Alto",IF(C31>6000,"Medio","Baixo")) | G31: =IF(Dados!H31="Sim","Ativo","Inativo")
A32: Tatiana | B32: Operações | C32: 6592.4 | D32: =IF(C32>12000,"Especialista",IF(C32>8000,"Senior",IF(C32>5000,"Pleno","Junior"))) | E32: =_xlfn.IFS(C32>12000,"Especialista",C32>8000,"Senior",C32>5000,"Pleno",TRUE,"Junior") | F32: =IF(C32>10000,"Alto",IF(C32>6000,"Medio","Baixo")) | G32: =IF(Dados!H32="Sim","Ativo","Inativo")
A33: Vinícius | B33: TI | C33: 14651.42 | D33: =IF(C33>12000,"Especialista",IF(C33>8000,"Senior",IF(C33>5000,"Pleno","Junior"))) | E33: =_xlfn.IFS(C33>12000,"Especialista",C33>8000,"Senior",C33>5000,"Pleno",TRUE,"Junior") | F33: =IF(C33>10000,"Alto",IF(C33>6000,"Medio","Baixo")) | G33: =IF(Dados!H33="Sim","Ativo","Inativo")
A34: Mariana | B34: Marketing | C34: 5008.97 | D34: =IF(C34>12000,"Especialista",IF(C34>8000,"Senior",IF(C34>5000,"Pleno","Junior"))) | E34: =_xlfn.IFS(C34>12000,"Especialista",C34>8000,"Senior",C34>5000,"Pleno",TRUE,"Junior") | F34: =IF(C34>10000,"Alto",IF(C34>6000,"Medio","Baixo")) | G34: =IF(Dados!H34="Sim","Ativo","Inativo")
A35: Leandro | C35: 8318 | D35: =IF(C35>12000,"Especialista",IF(C35>8000,"Senior",IF(C35>5000,"Pleno","Junior"))) | E35: =_xlfn.IFS(C35>12000,"Especialista",C35>8000,"Senior",C35>5000,"Pleno",TRUE,"Junior") | F35: =IF(C35>10000,"Alto",IF(C35>6000,"Medio","Baixo")) | G35: =IF(Dados!H35="Sim","Ativo","Inativo")
A36: Beatriz | B36: Marketing | C36: 9676.76 | D36: =IF(C36>12000,"Especialista",IF(C36>8000,"Senior",IF(C36>5000,"Pleno","Junior"))) | E36: =_xlfn.IFS(C36>12000,"Especialista",C36>8000,"Senior",C36>5000,"Pleno",TRUE,"Junior") | F36: =IF(C36>10000,"Alto",IF(C36>6000,"Medio","Baixo")) | G36: =IF(Dados!H36="Sim","Ativo","Inativo")
A37: Ricardo | B37: TI | C37: 7730.99 | D37: =IF(C37>12000,"Especialista",IF(C37>8000,"Senior",IF(C37>5000,"Pleno","Junior"))) | E37: =_xlfn.IFS(C37>12000,"Especialista",C37>8000,"Senior",C37>5000,"Pleno",TRUE,"Junior") | F37: =IF(C37>10000,"Alto",IF(C37>6000,"Medio","Baixo")) | G37: =IF(Dados!H37="Sim","Ativo","Inativo")
A38: Érica | B38: Vendas | C38: 10781.45 | D38: =IF(C38>12000,"Especialista",IF(C38>8000,"Senior",IF(C38>5000,"Pleno","Junior"))) | E38: =_xlfn.IFS(C38>12000,"Especialista",C38>8000,"Senior",C38>5000,"Pleno",TRUE,"Junior") | F38: =IF(C38>10000,"Alto",IF(C38>6000,"Medio","Baixo")) | G38: =IF(Dados!H38="Sim","Ativo","Inativo")
A39: Matheus | B39: Operações | C39: 4454.2 | D39: =IF(C39>12000,"Especialista",IF(C39>8000,"Senior",IF(C39>5000,"Pleno","Junior"))) | E39: =_xlfn.IFS(C39>12000,"Especialista",C39>8000,"Senior",C39>5000,"Pleno",TRUE,"Junior") | F39: =IF(C39>10000,"Alto",IF(C39>6000,"Medio","Baixo")) | G39: =IF(Dados!H39="Sim","Ativo","Inativo")
A40: Letícia | B40: RH | C40: 4949 | D40: =IF(C40>12000,"Especialista",IF(C40>8000,"Senior",IF(C40>5000,"Pleno","Junior"))) | E40: =_xlfn.IFS(C40>12000,"Especialista",C40>8000,"Senior",C40>5000,"Pleno",TRUE,"Junior") | F40: =IF(C40>10000,"Alto",IF(C40>6000,"Medio","Baixo")) | G40: =IF(Dados!H40="Sim","Ativo","Inativo")
...

Sheet Lookup
A1: Lookup — VLOOKUP, _xlfn.XLOOKUP, INDEX+MATCH
A2: ID Buscado | B2: VLOOKUP — Nome | C2: VLOOKUP — Departamento | D2: VLOOKUP — Salario | E2: _xlfn.XLOOKUP — Cargo | F2: INDEX+MATCH — Cidade | G2: IFERROR — seguro
A3: 1 | B3: =VLOOKUP(A3,Dados!$A$3:$H$54,2,FALSE) | C3: =VLOOKUP(A3,Dados!$A$3:$H$54,3,FALSE) | D3: =VLOOKUP(A3,Dados!$A$3:$H$54,6,FALSE) | E3: =_xlfn.XLOOKUP(A3,Dados!$A$3:$A$54,Dados!$D$3:$D$54,"Nao encontrado") | F3: =INDEX(Dados!$E$3:$E$54,MATCH(A3,Dados!$A$3:$A$54,0)) | G3: =IFERROR(VLOOKUP(A3,Dados!$A$3:$H$54,2,FALSE),"ID nao encontrado")
A4: 5 | B4: =VLOOKUP(A4,Dados!$A$3:$H$54,2,FALSE) | C4: =VLOOKUP(A4,Dados!$A$3:$H$54,3,FALSE) | D4: =VLOOKUP(A4,Dados!$A$3:$H$54,6,FALSE) | E4: =_xlfn.XLOOKUP(A4,Dados!$A$3:$A$54,Dados!$D$3:$D$54,"Nao encontrado") | F4: =INDEX(Dados!$E$3:$E$54,MATCH(A4,Dados!$A$3:$A$54,0)) | G4: =IFERROR(VLOOKUP(A4,Dados!$A$3:$H$54,2,FALSE),"ID nao encontrado")
A5: 10 | B5: =VLOOKUP(A5,Dados!$A$3:$H$54,2,FALSE) | C5: =VLOOKUP(A5,Dados!$A$3:$H$54,3,FALSE) | D5: =VLOOKUP(A5,Dados!$A$3:$H$54,6,FALSE) | E5: =_xlfn.XLOOKUP(A5,Dados!$A$3:$A$54,Dados!$D$3:$D$54,"Nao encontrado") | F5: =INDEX(Dados!$E$3:$E$54,MATCH(A5,Dados!$A$3:$A$54,0)) | G5: =IFERROR(VLOOKUP(A5,Dados!$A$3:$H$54,2,FALSE),"ID nao encontrado")
A6: 20 | B6: =VLOOKUP(A6,Dados!$A$3:$H$54,2,FALSE) | C6: =VLOOKUP(A6,Dados!$A$3:$H$54,3,FALSE) | D6: =VLOOKUP(A6,Dados!$A$3:$H$54,6,FALSE) | E6: =_xlfn.XLOOKUP(A6,Dados!$A$3:$A$54,Dados!$D$3:$D$54,"Nao encontrado") | F6: =INDEX(Dados!$E$3:$E$54,MATCH(A6,Dados!$A$3:$A$54,0)) | G6: =IFERROR(VLOOKUP(A6,Dados!$A$3:$H$54,2,FALSE),"ID nao encontrado")
A7: 35 | B7: =VLOOKUP(A7,Dados!$A$3:$H$54,2,FALSE) | C7: =VLOOKUP(A7,Dados!$A$3:$H$54,3,FALSE) | D7: =VLOOKUP(A7,Dados!$A$3:$H$54,6,FALSE) | E7: =_xlfn.XLOOKUP(A7,Dados!$A$3:$A$54,Dados!$D$3:$D$54,"Nao encontrado") | F7: =INDEX(Dados!$E$3:$E$54,MATCH(A7,Dados!$A$3:$A$54,0)) | G7: =IFERROR(VLOOKUP(A7,Dados!$A$3:$H$54,2,FALSE),"ID nao encontrado")
A8: 50 | B8: =VLOOKUP(A8,Dados!$A$3:$H$54,2,FALSE) | C8: =VLOOKUP(A8,Dados!$A$3:$H$54,3,FALSE) | D8: =VLOOKUP(A8,Dados!$A$3:$H$54,6,FALSE) | E8: =_xlfn.XLOOKUP(A8,Dados!$A$3:$A$54,Dados!$D$3:$D$54,"Nao encontrado") | F8: =INDEX(Dados!$E$3:$E$54,MATCH(A8,Dados!$A$3:$A$54,0)) | G8: =IFERROR(VLOOKUP(A8,Dados!$A$3:$H$54,2,FALSE),"ID nao encontrado")
A9: 99 | B9: =VLOOKUP(A9,Dados!$A$3:$H$54,2,FALSE) | C9: =VLOOKUP(A9,Dados!$A$3:$H$54,3,FALSE) | D9: =VLOOKUP(A9,Dados!$A$3:$H$54,6,FALSE) | E9: =_xlfn.XLOOKUP(A9,Dados!$A$3:$A$54,Dados!$D$3:$D$54,"Nao encontrado") | F9: =INDEX(Dados!$E$3:$E$54,MATCH(A9,Dados!$A$3:$A$54,0)) | G9: =IFERROR(VLOOKUP(A9,Dados!$A$3:$H$54,2,FALSE),"ID nao encontrado")
A12: Amarelo = VLOOKUP | Verde = _xlfn.XLOOKUP (Excel 365+) | Azul = INDEX+MATCH | Vermelho = IFERROR

Sheet Metricas
A1: Metricas Avancadas — Ranking, Top N, Percentual
A2: Nome | B2: Departamento | C2: Salario | D2: Ranking (RANK) | F2: Metrica | G2: Formula
A3: Ana | B3: Operações | C3: 2955.07 | D3: =IF(ISBLANK(C3), "", RANK(C3,$C$3:$C$54,0)) | F3: 1o maior salario | G3: =LARGE($C$3:$C$54,1)
A4: Carlos | C4: 4842.67 | D4: =IF(ISBLANK(C4), "", RANK(C4,$C$3:$C$54,0)) | F4: 2o maior salario | G4: =LARGE($C$3:$C$54,2)
A5: João | B5: Vendas | C5: 8303.39 | D5: =IF(ISBLANK(C5), "", RANK(C5,$C$3:$C$54,0)) | F5: 3o maior salario | G5: =LARGE($C$3:$C$54,3)
A6: Maria | B6: RH | C6: 4102.85 | D6: =IF(ISBLANK(C6), "", RANK(C6,$C$3:$C$54,0)) | F6: 1o menor salario | G6: =SMALL($C$3:$C$54,1)
A7: Pedro | B7: Financeiro | D7: =IF(ISBLANK(C7), "", RANK(C7,$C$3:$C$54,0)) | F7: Mediana | G7: =MEDIAN($C$3:$C$54)
A8: Fernanda | B8: RH | C8: 9059.57 | D8: =IF(ISBLANK(C8), "", RANK(C8,$C$3:$C$54,0)) | F8: Desvio Padrao | G8: =STDEV($C$3:$C$54)
A9: Lucas | B9: RH | C9: 7459.35 | D9: =IF(ISBLANK(C9), "", RANK(C9,$C$3:$C$54,0)) | F9: % acima da media | G9: =COUNTIF($C$3:$C$54,">"&AVERAGE($C$3:$C$54))/COUNTA($C$3:$C$54)
A10: Juliana | B10: Marketing | D10: =IF(ISBLANK(C10), "", RANK(C10,$C$3:$C$54,0)) | F10: Folha top 3 | G10: =LARGE($C$3:$C$54,1)+LARGE($C$3:$C$54,2)+LARGE($C$3:$C$54,3)
A11: Rafael | B11: Marketing | C11: 4701.01 | D11: =IF(ISBLANK(C11), "", RANK(C11,$C$3:$C$54,0))
A12: Camila | B12: Operações | D12: =IF(ISBLANK(C12), "", RANK(C12,$C$3:$C$54,0))
A13: Bruno | B13: Operações | C13: 7710.89 | D13: =IF(ISBLANK(C13), "", RANK(C13,$C$3:$C$54,0))
A14: Larissa | B14: TI | C14: 13862.23 | D14: =IF(ISBLANK(C14), "", RANK(C14,$C$3:$C$54,0))
A15: Diego | B15: Operações | C15: 8825.71 | D15: =IF(ISBLANK(C15), "", RANK(C15,$C$3:$C$54,0))
A16: Patrícia | B16: Vendas | C16: 9862.6 | D16: =IF(ISBLANK(C16), "", RANK(C16,$C$3:$C$54,0))
A17: Thiago | B17: RH | D17: =IF(ISBLANK(C17), "", RANK(C17,$C$3:$C$54,0))
A18: Renata | B18: Vendas | C18: 8937.76 | D18: =IF(ISBLANK(C18), "", RANK(C18,$C$3:$C$54,0))
A19: Felipe | B19: Operações | C19: 7220.28 | D19: =IF(ISBLANK(C19), "", RANK(C19,$C$3:$C$54,0))
A20: Daniela | C20: 7324.01 | D20: =IF(ISBLANK(C20), "", RANK(C20,$C$3:$C$54,0))
A21: Rodrigo | B21: RH | C21: 6842.01 | D21: =IF(ISBLANK(C21), "", RANK(C21,$C$3:$C$54,0))
A22: Amanda | B22: Vendas | C22: 10267.47 | D22: =IF(ISBLANK(C22), "", RANK(C22,$C$3:$C$54,0))
A23: Gustavo | B23: Operações | C23: 3175.8 | D23: =IF(ISBLANK(C23), "", RANK(C23,$C$3:$C$54,0))
A24: Vanessa | B24: RH | C24: 5123.74 | D24: =IF(ISBLANK(C24), "", RANK(C24,$C$3:$C$54,0))
A25: Eduardo | B25: TI | D25: =IF(ISBLANK(C25), "", RANK(C25,$C$3:$C$54,0))
A26: Aline | B26: Financeiro | C26: 9364.59 | D26: =IF(ISBLANK(C26), "", RANK(C26,$C$3:$C$54,0))
A27: Marcos | B27: Marketing | C27: 8983.8 | D27: =IF(ISBLANK(C27), "", RANK(C27,$C$3:$C$54,0))
A28: Cristina | B28: TI | C28: 5890.78 | D28: =IF(ISBLANK(C28), "", RANK(C28,$C$3:$C$54,0))
A29: Leonardo | B29: TI | C29: 10449.92 | D29: =IF(ISBLANK(C29), "", RANK(C29,$C$3:$C$54,0))
A30: Priscila | C30: 12224.44 | D30: =IF(ISBLANK(C30), "", RANK(C30,$C$3:$C$54,0))
A31: André | B31: Marketing | C31: 7047.08 | D31: =IF(ISBLANK(C31), "", RANK(C31,$C$3:$C$54,0))
A32: Tatiana | B32: Operações | C32: 6592.4 | D32: =IF(ISBLANK(C32), "", RANK(C32,$C$3:$C$54,0))
A33: Vinícius | B33: TI | C33: 14651.42 | D33: =IF(ISBLANK(C33), "", RANK(C33,$C$3:$C$54,0))
A34: Mariana | B34: Marketing | C34: 5008.97 | D34: =IF(ISBLANK(C34), "", RANK(C34,$C$3:$C$54,0))
A35: Leandro | C35: 8318 | D35: =IF(ISBLANK(C35), "", RANK(C35,$C$3:$C$54,0))
A36: Beatriz | B36: Marketing | C36: 9676.76 | D36: =IF(ISBLANK(C36), "", RANK(C36,$C$3:$C$54,0))
A37: Ricardo | B37: TI | C37: 7730.99 | D37: =IF(ISBLANK(C37), "", RANK(C37,$C$3:$C$54,0))
A38: Érica | B38: Vendas | C38: 10781.45 | D38: =IF(ISBLANK(C38), "", RANK(C38,$C$3:$C$54,0))
A39: Matheus | B39: Operações | C39: 4454.2 | D39: =IF(ISBLANK(C39), "", RANK(C39,$C$3:$C$54,0))
A40: Letícia | B40: RH | C40: 4949 | D40: =IF(ISBLANK(C40), "", RANK(C40,$C$3:$C$54,0))
...
